Workbook

Sheet Peněžní deník 2025
M4: =SUM(M9:M67) -> 0 | N4: =SUM(N9:N67) -> 0 | O4: =SUM(O9:O67) -> 0 | P4: =SUM(P9:P67) -> 0 | Q4: =SUM(Q9:Q67) -> 0 | R4: =SUM(R9:R67) -> 0 | S4: =SUM(S9:S67) -> 0 | T4: =SUM(T9:T67) -> 0 | ... AH4: =SUM(AH9:AH67) -> 0
A5: Č. ř. | B5: Datum | C5: Doklad | D5: Účet | E5: Projekt | F5: TEXT | G5: Peněžní prostředky v hotovosti | I5: Peněžní prostředky na bankovních účtech | K5: Průběžné položky | M5: Příjmy celkem | N5: Výdaje celkem | O5: Příjmy podle stanov, příjmy osvobozené a zdaněné srážkovou daní | X5: Nedaňové příjmy celkem | Y5: Výdaje z činností podle stanov a srážková daň | AI5: Nedaňové výdaje celkem
O6: Prodej zboží | P6: Prodej výrobků a služeb | Q6: Příjmy z veřejných sbírek | R6: Přijaté peněžní dary mimo veřejné sbírky | S6: Přijaté členské příspěvky | T6: Dotace a příspěvky přijaté z veřej. rozpočtů | U6: Ostatní | V6: Průběžné položky | W6: Kursové rozdíly | Y6: Dlouhodobý nehmotný a hmotný majetek | Z6: Materiál | AA6: Zboží | AB6: Služby | AC6: Mzdy | AD6: Pojistné za zaměstnance a zaměstnavatele | AE6: Ostatní osobní výdaje | AF6: Ostatní | AG6: Průběžné položky | AH6: Kursové rozdíly | AJ6: Účel
G7: Příjem | H7: Výdaj | I7: Příjem | J7: Výdaj | K7: Příjem | L7: Výdaj | M7: (sl. 7+9) | N7: (sl. 8+10) | O7: 09 | P7: 10 | Q7: 11 | R7: 11 | S7: 21 | T7: 11 | U7: 11 | V7: 29 | W7: 11 | Y7: 22 | Z7: 12 | AA7: 13 | AB7: 28 | AC7: 14 | AD7: 15 | AE7: 26 | AF7: 28 | AG7: 30 | AH7: 28
A8: 1 | B8: 2 | C8: 3 | D8: 4 | E8: 5 | F8: 6 | G8: 7 | H8: 8 | I8: 9 | J8: 10 | K8: 11 | L8: 12 | M8: 7 | N8: 8 | O8: 9 | P8: 10 | Q8: 11 | R8: 12 | S8: 13 | T8: 14 | U8: 15 | V8: 16 | W8: 17 | X8: 18 | Y8: 19 | Z8: 20 | AA8: 21 | AB8: 22 | AC8: 23 | AD8: 24 | AE8: 25 | AF8: 26 | AG8: 27 | AH8: 28 | AI8: 29 | AJ8: 44
A9: 1
A10: 2 | AJ10: Platba za aranž Slunečný hrob
A11: 3 | AJ11: Převoz kláves (LAMEN)
A12: 4 | AJ12: Píra mimino
A13: 5 | AJ13: KP Smíchov - LAMEN Praha
A14: 6 | AJ14: Kasička na vstupné
A15: 7 | AJ15: Vyrovnání s Lukášem za kravaty
A16: 8 | AJ16: LAMEN doplňky
A17: 9 | AJ17: Vstupné LAMEN (QR platba)
A18: 10 | AJ18: Vstupné LAMEN cash (Praha)
A19: 11 | AJ19: Vstupné LAMEN cash (Rokycany)
A20: 12 | AG20: =N20 -> 0 | AI20: =AG20 -> 0 | AJ20: Vstupné LAMEN (QR platba)
A21: 13 | AJ21: Převod - výběr z pokladny
A22: 14 | AJ22: Převod - připsáno na účet
A23: 15 | AJ23: Vincentky
A24: 16 | AJ24: Podíl pro Lamas (LAMEN 2024)
A25: 17 | AJ25: Káva v kapslích Nespresso
A26: 18 | AJ26: Vstupné - koncert s Amíkama
A27: 19 | AJ27: Busking v Ústí
A28: 20 | AJ28: Erár víno z Malých Žernosek
A29: 21 | AJ29: Za degustaci
A30: 22 | AJ30: Záloha na sud piva (Bart vrátit!)
A31: 23 | AJ31: Honorář za vystoupení na IFAS
A32: 24 | AJ32: Honorář za vystoupení na oslavě
... A34: 26 | AJ34: Odvápňovací sada do kávovaru
A35: 27 | AG35: =N35 -> 0 | AJ35: 3/4 honoráře z Chemnitz
A36: 28 | AJ36: Adrian - doprava IFAS
A37: 29 | AJ37: Kryštof M. - doprava IFAS
A38: 30 | AG38: =N38 -> 0 | AJ38: Šálky do zkušebny
A39: 31 | AJ39: Zásobník na kafe a čaje
A40: 32 | AJ40: Jirkov - startovné
A41: 33 | AJ41: Lžičky
A42: 34 | AJ42: Jirkov - jídlo
A43: 35 | AJ43: Vrácená záloha na sud
A44: 36 | AJ44: Všechlapy
...

Sheet Přehled o P a V 2025
A1: PŘEHLED O PŘÍJMECH A VÝDAJÍCH
A3: Jméno a příjmení / Název firmy: | D3: Zapsán do VR dne: | E3: 45349
A4: Vokální skupina 10men, z. s. | D4: Právní forma: | E4: Spolek
D5: V likvidaci: | E5: ANO / NE
A6: Adresa: | B6: Smetanovo nábřeží 330/16, Staré Město, 110 00 Praha 1 | D6: Předmět podnikání: | E6: Provozování pěvecké činnosti, pořádání hudebních produkcí a představení.
A8: IČ: | B8: 21194297 | D8: Okamžik sestavení účetní závěrky:
A10: Období:
D11: Sestaveno dne:
C12: (V celých tisících)
C14: Číslo řádku | D14: Činnost
D15: Hlavní | E15: Hospodářská | F15: Celkem
A16: A. | B16: Příjmy
A17: 1 | B17: Prodej zboží | C17: 1 | D17: ='Peněžní deník 2025'!O68/1000 -> 0 | E17: 0 | F17: =D17+E17 -> 0
A18: 2 | B18: Prodej výrobků a služeb | C18: 2 | D18: ='Peněžní deník 2025'!P68/1000 -> 0 | E18: 0 | F18: =D18+E18 -> 0
A19: 3 | B19: Příjmy z veřejných sbírek | C19: 3 | D19: ='Peněžní deník 2025'!Q68/1000 -> 0 | E19: 0 | F19: =D19+E19 -> 0
A20: 4 | B20: Přijaté peněžní dary mimo veřejné sbírky | C20: 4 | D20: ='Peněžní deník 2025'!R68/1000 -> 0 | E20: 0 | F20: =D20+E20 -> 0
A21: 5 | B21: Přijaté členské příspěvky | C21: 5 | D21: ='Peněžní deník 2025'!S68/1000 -> 0 | E21: 0 | F21: =D21+E21 -> 0
A22: 6 | B22: Dotace a příspěvky přijaté z veřej. rozpočtů | C22: 6 | D22: ='Peněžní deník 2025'!T68/1000 -> 0 | E22: 0 | F22: =D22+E22 -> 0
A23: 7 | B23: Ostatní | C23: 7 | D23: ='Peněžní deník 2025'!U68/1000 -> 0 | E23: 0 | F23: =D23+E23 -> 0
A24: 8 | B24: Průběžné položky | C24: 8 | D24: ='Peněžní deník 2025'!V68/1000 -> 0 | E24: 0 | F24: =D24+E24 -> 0
A25: 9 | B25: Kursové rozdíly | C25: 9 | D25: ='Peněžní deník 2025'!W74/1000 -> 0 | E25: 0 | F25: =D25+E25 -> 0
A26: 10 | B26: Příjmy celkem | C26: 10 | D26: =SUM(D17:D25) -> 0 | F26: =D26+E26 -> 0
A27: B. | B27: Výdaje
A28: 1 | B28: Dlouhodobý nehmotný a hmotný majetek | C28: 11 | D28: ='Peněžní deník 2025'!Y68/1000 -> 0 | F28: =D28+E28 -> 0 | K28: ;
A29: 2 | B29: Materiál | C29: 12 | D29: ='Peněžní deník 2025'!Z68/1000 -> 0 | F29: =D29+E29 -> 0
A30: 3 | B30: Zboží | C30: 13 | D30: ='Peněžní deník 2025'!AA68/1000 -> 0 | F30: =D30+E30 -> 0
A31: 4 | B31: Služby | C31: 14 | D31: ='Peněžní deník 2025'!AB68/1000 -> 0 | F31: =D31+E31 -> 0
A32: 5 | B32: Mzdy | C32: 15 | D32: ='Peněžní deník 2025'!AC68/1000 -> 0 | F32: =D32+E32 -> 0
A33: 6 | B33: Pojistné za zaměstnance a zaměstnavatele | C33: 16 | D33: ='Peněžní deník 2025'!AD68/1000 -> 0 | F33: =D33+E33 -> 0
A34: 7 | B34: Ostatní osobní výdaje | C34: 17 | D34: ='Peněžní deník 2025'!AE68/1000 -> 0 | F34: =D34+E34 -> 0
A35: 8 | B35: Ostatní | C35: 18 | D35: ='Peněžní deník 2025'!AF68/1000 -> 0 | F35: =D35+E35 -> 0
A36: 9 | B36: Průběžné položky | C36: 19 | D36: ='Peněžní deník 2025'!AG68/1000 -> 0 | F36: =D36+E36 -> 0
A37: 10 | B37: Kursové rozdíly | C37: 20 | D37: ='Peněžní deník 2025'!AH68/1000 -> 0 | F37: =D37+E37 -> 0
A38: 11 | B38: Výdaje celkem | C38: 21 | D38: =SUM(D28:D37) -> 0 | E38: =SUM(E28:E37) -> 0 | F38: =D38+E38 -> 0
A39: 99 | B39: ROZDÍL PŘÍJMŮ A VÝDAJŮ | C39: 22 | D39: =D26-D38 -> 0 | E39: =E26-E38 -> 0 | F39: =D39+E39 -> 0
A41: Podpisový záznam statutárního orgánu: | D41: Podpisový záznam účetní jednotky:

Sheet Přehled o M a Z 2025
A1: PŘEHLED O MAJETKU A ZÁVAZCÍCH
A3: Jméno a příjmení / Název firmy: | D3: Zapsán do VR dne: | E3: 45349
A4: Vokální skupina 10men, z. s. | D4: Právní forma: | E4: Spolek
D5: V likvidaci: | E5: ANO / NE
A6: Adresa: | B6: Smetanovo nábřeží 330/16, Staré Město, 110 00 Praha 1 | D6: Předmět podnikání: | E6: Provozování pěvecké činnosti, pořádání hudebních produkcí a představení.
A8: IČ: | B8: 21194297 | D8: Okamžik sestavení účetní závěrky:
A10: Období:
D11: Sestaveno dne:
C12: (V celých tisících)
C14: Běžné účetní období | E14: Minulé účetní období
A15: 1 | B15: Dlouhodobý nehmotný majetek
A16: 2 | B16: Dlouhodobý hmotný majetek
A17: 3 | B17: Finanční majetek
A18: 4 | B18: Peněžní prostředky v hotovosti a ceniny | C18: ='Peněžní deník 2025'!M87/1000 -> 3.04 | E18: 10
A19: 5 | B19: Peněžní prostředky na bankovních účtech | C19: ='Peněžní deník 2025'!M88/1000 -> -3.04 | E19: 29
A20: 6 | B20: Zásoby
A21: 7 | B21: Pohledávky
A22: 8 | B22: Úvěry a zápůjčky poskytnuté
A23: 9 | B23: Ostatní majetek
A24: 10 | B24: Majetek celkem | C24: =SUM(C15:C23) -> 0 | E24: =SUM(E15:E23) -> 39
A25: 1 | B25: Závazky
A26: 2 | B26: Úvěry a zápůjčky přijaté
A27: 3 | B27: Závazky celkem | C27: =SUM(C25:C26) -> 0 | E27: =SUM(E25:E26) -> 0
A28: 99 | B28: ROZDÍL MAJETKU A ZÁVAZKŮ | C28: =C24-C27 -> 0 | E28: =E24-E27 -> 39
A30: Podpisový záznam statutárního orgánu: | D30: Podpisový záznam účetní jednotky:

Sheet Manuál
A1: POLOŽKA | B1: KATEGORIE | C1: Stereo
A2: Příjmy
A3: Výtěžky z koncertů - výběr vstupného, honoráře za koncerty, obsah klobouku z buskingu | B3: Prodej výrobků a služeb | C3: PVS
A4: Merch - prodej CD a drobných dárkových předmětů | B4: Prodej výrobků a služeb | C4: PVS
A5: Členské příspěvky - převedení členských příspěvků na spolkový účet | B5: Přijaté členské příspěvky | C5: PCP
A6: Bezúročné půjčky od členů - když nejsou peníze, můžeme spolku půjčit ze svého (na smlouvu) | B6: Ostatní | C6: PP
A7: Dary - osoba nebo firma pošle peníze spolku jako dar | B7: Přijaté peněžní dary mimo veřejné sbírky | C7: PMV
A9: Výdaje
A10: Občerstvení na schůzi či zkoušku - Nespresso kapsle, sušenky, Vincentnky - obecně jídlo a pití ze supermarketu | B10: Materiál | C10: MT
A11: Drobné věci - koncertní trička, oblečení, doplňky, kravaty, kancelářské potřeby, baterky, kabely a příslušenství ke klávesám, stativům… | B11: Materiál | C11: MT
A12: Organizování koncertu - pronájem sálu a další služby, odměny fotografům a nasmlouvanému personálu, catering & welcome drinky, květiny na děkovačku | B12: Služby | C12: SL
A13: Soutěž / soustředění - faktura za ubytování, zajištění stravy, účastnický poplatek | B13: Služby | C13: SL
A14: Provozní věci - faktura za webhosting, mobilní tarif, poplatky na poště, proplacení lístků na vlak, bankovní poplatky | B14: Služby | C14: SL
A15: Podíly ze zisku - jiným sborům ze společných koncertů, za dárky sbormistrům (alkohol, peníze)… | B15: Ostatní | C15: OST
